Workbook

Sheet README
A1: Dietary Fiber Strategy — GHG Emission Intensity vs. Farm Economics
A3: PURPOSE
A4: Constrained-optimization analysis linking dietary fiber composition (NDF, ADF, hemicellulose) to
A5: enteric methane emission intensity AND feed-cost economics, using the Niu et al. (2018) methane
A6: prediction equation. Diets are formulated de novo and cost-minimized at each dietary NDF level
A7: (rather than compared as a small fixed set of scenarios or inferred from regional correlation),
A8: directly quantifying the joint GHG and farm-economic consequences of dietary fiber composition.
A10: STRUCTURE
A11: 1. Ingredients - feed composition (NASEM/published feed library values) and current U.S. prices
A12: 2. Diet Scenarios - 9 formulated diets: 3 forage sources x 3 forage:concentrate ratios
A13: 3. Calculations - DMI, ECM, enteric CH4 (Niu et al. 2018), GHG intensity, feed cost, IOFC
A14: 4. Results - summary trade-off table (kg CO2e/kg FPCM vs. $/cwt margin) + marginal cost curve
... A47: once byproducts are available to the optimizer.

Sheet Ingredients
A1: Ingredient | B1: DM % | C1: NDF %DM | D1: ADF %DM | E1: CP %DM | F1: NEL (Mcal/kg DM) | G1: Price ($/ton as-fed) | H1: Price ($/kg DM) | I1: Hemicellulose %DM (NDF-ADF) | J1: Source / note
A2: Alfalfa haylage | B2: 0.45 | C2: 0.4 | D2: 0.32 | E2: 0.2 | F2: 1.3 | G2: 195 | H2: =G2/907.185/B2 -> 0.4776681 | I2: =C2-D2 -> 0.08 | J2: USDA NASS Agricultural Prices, alfalfa hay, national avg, mid-2026 (haylage priced as hay-DM equivalent)
A3: Corn silage | B3: 0.35 | C3: 0.45 | D3: 0.26 | E3: 0.08 | F3: 1.55 | G3: 52 | H3: =G3/907.185/B3 -> 0.16377192 | I3: =C3-D3 -> 0.19 | J3: Univ. of Missouri Extension, 2026 Corn Silage Planning Budget (G664): total economic cost (operating+ownership, land-opportunity-cost basis, matching ARMS costing philosophy) = $52.36/ton as-fed ($149.60/ton DM)
A4: Grass hay | B4: 0.88 | C4: 0.58 | D4: 0.35 | E4: 0.11 | F4: 1.2 | G4: 145 | H4: =G4/907.185/B4 -> 0.18163079 | I4: =C4-D4 -> 0.23 | J4: USDA AMS/NASS grass & grass-mix hay, national avg, mid-2026
A5: Corn grain, ground | B5: 0.88 | C5: 0.09 | D5: 0.03 | E5: 0.09 | F5: 1.9 | G5: 155 | H5: =G5/907.185/B5 -> 0.19415705 | I5: =C5-D5 -> 0.06 | J5: USDA NASS corn price ~$4.35/bu converted to $/ton (56 lb/bu)
A6: Soybean meal, 48% | B6: 0.9 | C6: 0.08 | D6: 0.06 | E6: 0.48 | F6: 1.98 | G6: 305 | H6: =G6/907.185/B6 -> 0.37356095 | I6: =C6-D6 -> 0.02 | J6: USDA WASDE / NASS soybean meal, 48% CP, national avg, mid-2026
A8: Milk price ($/cwt) | B8: 21 | C8: USDA NASS all-milk price, most recent reported month (May 2026: $21.30/cwt) - UPDATE to submission-month figure before final draft
A10: Methane energy density (MJ/kg CH4) | B10: 55.65 | C10: Brouwer (1965); standard gross energy value of methane
A11: CH4 GWP-100 (kg CO2e / kg CH4) | B11: 27.9 | C11: IPCC AR6 (2021) fossil/biogenic methane GWP-100 - cite IPCC AR6 WG1 Ch.7 in manuscript
A12: Mineral/vitamin/additive premix ($/cow/day) | B12: 0.55 | C12: Typical commercial premix cost not captured by the 2-ingredient concentrate mix; added as a flat daily cost so feed-cost/cwt is comparable to ARMS-reported figures
A14: NOTE ON FORAGE PRICING BASIS
A15: Corn silage price is the University of Missouri Extension 2026 Corn Silage Planning Budget (G664)
A16: total economic cost estimate ($52.36/ton as-fed = $149.60/ton DM), which includes land opportunity
A17: cost, machinery, and harvest -- matching the ARMS 'full economic cost of home-grown feed' basis used
A18: in this study, rather than a spot/standing-crop market price (which would be lower, ~$27-47/ton
A19: as-fed per Ohio State Extension). An earlier draft of this model used an uncited $200/ton placeholder;
A20: this has been corrected and sourced. Re-verify against local budgets before final submission.
A22: ADDITIONAL INGREDIENTS (Ingredient Library Robustness sheet ONLY -- not used in primary 5-ingredient model above)
A23: DDGS (distillers dried grains w/ solubles) | B23: 0.9 | C23: 0.35 | D23: 0.15 | E23: 0.3 | F23: 1.9 | G23: 150 | H23: =G23/907.185/B23 -> 0.1837185 | I23: =C23-D23 -> 0.2 | J23: Purdue Center for Commercial Agriculture / farmdoc, late-2025/early-2026 futures-linked DDG price projection ($145-155/ton); used ONLY in the Ingredient Library Robustness sheet, not the primary 5-ingredient model.
A24: Soybean hulls | B24: 0.9 | C24: 0.67 | D24: 0.47 | E24: 0.12 | F24: 1.68 | G24: 140 | H24: =G24/907.185/B24 -> 0.1714706 | I24: =C24-D24 -> 0.2 | J24: Composition: Blasi et al., 2000 (Kansas State Univ. MF-2438). Price: illustrative 2026 byproduct estimate, ~90% of corn grain price/ton; used ONLY in the Ingredient Library Robustness sheet, not the primary 5-ingredient model.

Sheet Diet Scenarios
A1: Scenario | B1: Forage source | C1: Forage:Conc ratio | D1: Forage %DM of diet | E1: Concentrate %DM of diet | F1: Corn grain % of concentrate | G1: SBM % of concentrate | H1: Diet NDF %DM | I1: Diet ADF %DM | J1: Diet Hemicellulose %DM | K1: Diet CP %DM | L1: Diet NEL (Mcal/kg DM)
A2: S1 | B2: Alfalfa haylage | C2: 45:55 | D2: 0.45 | E2: =1-D2 -> 0.55 | F2: 0.8 | G2: =1-F2 -> 0.2 | H2: =D2*Ingredients!$C$2+E2*(F2*Ingredients!$C$5+G2*Ingredients!$C$6) -> 0.2284 | I2: =D2*Ingredients!$D$2+E2*(F2*Ingredients!$D$5+G2*Ingredients!$D$6) -> 0.1638 | J2: =H2-I2 -> 0.0646 | K2: =D2*Ingredients!$E$2+E2*(F2*Ingredients!$E$5+G2*Ingredients!$E$6) -> 0.1824 | L2: =D2*Ingredients!$F$2+E2*(F2*Ingredients!$F$5+G2*Ingredients!$F$6) -> 1.6388
A3: S2 | B3: Alfalfa haylage | C3: 50:50 | D3: 0.5 | E3: =1-D3 -> 0.5 | F3: 0.8 | G3: =1-F3 -> 0.2 | H3: =D3*Ingredients!$C$2+E3*(F3*Ingredients!$C$5+G3*Ingredients!$C$6) -> 0.244 | I3: =D3*Ingredients!$D$2+E3*(F3*Ingredients!$D$5+G3*Ingredients!$D$6) -> 0.178 | J3: =H3-I3 -> 0.066 | K3: =D3*Ingredients!$E$2+E3*(F3*Ingredients!$E$5+G3*Ingredients!$E$6) -> 0.184 | L3: =D3*Ingredients!$F$2+E3*(F3*Ingredients!$F$5+G3*Ingredients!$F$6) -> 1.608
A4: S3 | B4: Alfalfa haylage | C4: 55:45 | D4: 0.55 | E4: =1-D4 -> 0.45 | F4: 0.8 | G4: =1-F4 -> 0.2 | H4: =D4*Ingredients!$C$2+E4*(F4*Ingredients!$C$5+G4*Ingredients!$C$6) -> 0.2596 | I4: =D4*Ingredients!$D$2+E4*(F4*Ingredients!$D$5+G4*Ingredients!$D$6) -> 0.1922 | J4: =H4-I4 -> 0.0674 | K4: =D4*Ingredients!$E$2+E4*(F4*Ingredients!$E$5+G4*Ingredients!$E$6) -> 0.1856 | L4: =D4*Ingredients!$F$2+E4*(F4*Ingredients!$F$5+G4*Ingredients!$F$6) -> 1.5772
A5: S4 | B5: Corn silage | C5: 45:55 | D5: 0.45 | E5: =1-D5 -> 0.55 | F5: 0.8 | G5: =1-F5 -> 0.2 | H5: =D5*Ingredients!$C$3+E5*(F5*Ingredients!$C$5+G5*Ingredients!$C$6) -> 0.2509 | I5: =D5*Ingredients!$D$3+E5*(F5*Ingredients!$D$5+G5*Ingredients!$D$6) -> 0.1368 | J5: =H5-I5 -> 0.1141 | K5: =D5*Ingredients!$E$3+E5*(F5*Ingredients!$E$5+G5*Ingredients!$E$6) -> 0.1284 | L5: =D5*Ingredients!$F$3+E5*(F5*Ingredients!$F$5+G5*Ingredients!$F$6) -> 1.7513
A6: S5 | B6: Corn silage | C6: 50:50 | D6: 0.5 | E6: =1-D6 -> 0.5 | F6: 0.8 | G6: =1-F6 -> 0.2 | H6: =D6*Ingredients!$C$3+E6*(F6*Ingredients!$C$5+G6*Ingredients!$C$6) -> 0.269 | I6: =D6*Ingredients!$D$3+E6*(F6*Ingredients!$D$5+G6*Ingredients!$D$6) -> 0.148 | J6: =H6-I6 -> 0.121 | K6: =D6*Ingredients!$E$3+E6*(F6*Ingredients!$E$5+G6*Ingredients!$E$6) -> 0.124 | L6: =D6*Ingredients!$F$3+E6*(F6*Ingredients!$F$5+G6*Ingredients!$F$6) -> 1.733
A7: S6 | B7: Corn silage | C7: 55:45 | D7: 0.55 | E7: =1-D7 -> 0.45 | F7: 0.8 | G7: =1-F7 -> 0.2 | H7: =D7*Ingredients!$C$3+E7*(F7*Ingredients!$C$5+G7*Ingredients!$C$6) -> 0.2871 | I7: =D7*Ingredients!$D$3+E7*(F7*Ingredients!$D$5+G7*Ingredients!$D$6) -> 0.1592 | J7: =H7-I7 -> 0.1279 | K7: =D7*Ingredients!$E$3+E7*(F7*Ingredients!$E$5+G7*Ingredients!$E$6) -> 0.1196 | L7: =D7*Ingredients!$F$3+E7*(F7*Ingredients!$F$5+G7*Ingredients!$F$6) -> 1.7147
A8: S7 | B8: Grass hay | C8: 45:55 | D8: 0.45 | E8: =1-D8 -> 0.55 | F8: 0.8 | G8: =1-F8 -> 0.2 | H8: =D8*Ingredients!$C$4+E8*(F8*Ingredients!$C$5+G8*Ingredients!$C$6) -> 0.3094 | I8: =D8*Ingredients!$D$4+E8*(F8*Ingredients!$D$5+G8*Ingredients!$D$6) -> 0.1773 | J8: =H8-I8 -> 0.1321 | K8: =D8*Ingredients!$E$4+E8*(F8*Ingredients!$E$5+G8*Ingredients!$E$6) -> 0.1419 | L8: =D8*Ingredients!$F$4+E8*(F8*Ingredients!$F$5+G8*Ingredients!$F$6) -> 1.5938
A9: S8 | B9: Grass hay | C9: 50:50 | D9: 0.5 | E9: =1-D9 -> 0.5 | F9: 0.8 | G9: =1-F9 -> 0.2 | H9: =D9*Ingredients!$C$4+E9*(F9*Ingredients!$C$5+G9*Ingredients!$C$6) -> 0.334 | I9: =D9*Ingredients!$D$4+E9*(F9*Ingredients!$D$5+G9*Ingredients!$D$6) -> 0.193 | J9: =H9-I9 -> 0.141 | K9: =D9*Ingredients!$E$4+E9*(F9*Ingredients!$E$5+G9*Ingredients!$E$6) -> 0.139 | L9: =D9*Ingredients!$F$4+E9*(F9*Ingredients!$F$5+G9*Ingredients!$F$6) -> 1.558
A10: S9 | B10: Grass hay | C10: 55:45 | D10: 0.55 | E10: =1-D10 -> 0.45 | F10: 0.8 | G10: =1-F10 -> 0.2 | H10: =D10*Ingredients!$C$4+E10*(F10*Ingredients!$C$5+G10*Ingredients!$C$6) -> 0.3586 | I10: =D10*Ingredients!$D$4+E10*(F10*Ingredients!$D$5+G10*Ingredients!$D$6) -> 0.2087 | J10: =H10-I10 -> 0.1499 | K10: =D10*Ingredients!$E$4+E10*(F10*Ingredients!$E$5+G10*Ingredients!$E$6) -> 0.1361 | L10: =D10*Ingredients!$F$4+E10*(F10*Ingredients!$F$5+G10*Ingredients!$F$6) -> 1.5222
A12: Note: corn:SBM split (col F) is a free lever, defaulted to 80:20; adjust per scenario so diet CP (col K) lands near a 16.0-17.0% DM target before finalizing for the manuscript.

Sheet Calculations
A1: Scenario | B1: Forage source | C1: Ratio | D1: BW (kg) | E1: Milk yield (kg/d) | F1: Fat % | G1: CP %(milk) | H1: ECM (kg/d) | I1: NEm (Mcal/d) | J1: NEl milk (Mcal/d) | K1: DMI (kg/d) | L1: CH4 (MJ/d, Niu 2018) | M1: CH4 (kg/d) | N1: CH4 CO2e (kg/d) | O1: FPCM (kg/d) | P1: GHG intensity (kg CO2e/kg FPCM) | Q1: Feed cost ($/d) | R1: Feed cost ($/cwt milk) | S1: Milk revenue ($/d) | T1: IOFC ($/d) | U1: IOFC ($/cwt) | W1: Fixed cow assumptions (held constant across scenarios):
A2: ='Diet Scenarios'!A2 -> S1 | B2: ='Diet Scenarios'!B2 -> Alfalfa haylage | C2: ='Diet Scenarios'!C2 -> 45:55 | D2: =$X$2 -> 650 | E2: =$X$3 -> 38 | F2: =$X$4 -> 3.8 | G2: =$X$5 -> 3.1 | H2: =0.327*E2+12.95*(E2*F2/100)+7.2*(E2*G2/100) -> 39.6074 | I2: =$X$6*D2^0.75 -> 10.298524 | J2: =E2*$X$7 -> 28.12 | K2: =(I2+J2)/'Diet Scenarios'!L2 -> 23.443083 | L2: =13.3+0.118*('Diet Scenarios'!H2*100)-0.13*H2+2.2*F2-1.71*G2+0.00521*D2 -> 17.291658 | M2: =L2/Ingredients!$B$10 -> 0.31072162 | N2: =M2*Ingredients!$B$11 -> 8.6691331 | O2: =E2*(0.337+0.116*F2+0.06*G2) -> 36.6244 | P2: =N2/O2 -> 0.23670376 | Q2: =K2*('Diet Scenarios'!D2*INDEX(Ingredients!$H$2:$H$6,MATCH('Diet Scenarios'!B2,Ingredients!$A$2:$A$6,0))+'Diet Scenarios'!E2*('Diet Scenarios'!F2*Ingredients!$H$5+'Diet Scenarios'!G2*Ingredients!$H$6))+Ingredients!$B$12 -> 8.5551436 | R2: =Q2/(E2/45.359237) -> 10.211968 | S2: =(E2/45.359237)*Ingredients!$B$8 -> 17.592889 | T2: =S2-Q2 -> 9.037745 | U2: =T2/(E2/45.359237) -> 10.788032 | W2: BW (kg) | X2: 650
A3: ='Diet Scenarios'!A3 -> S2 | B3: ='Diet Scenarios'!B3 -> Alfalfa haylage | C3: ='Diet Scenarios'!C3 -> 50:50 | D3: =$X$2 -> 650 | E3: =$X$3 -> 38 | F3: =$X$4 -> 3.8 | G3: =$X$5 -> 3.1 | H3: =0.327*E3+12.95*(E3*F3/100)+7.2*(E3*G3/100) -> 39.6074 | I3: =$X$6*D3^0.75 -> 10.298524 | J3: =E3*$X$7 -> 28.12 | K3: =(I3+J3)/'Diet Scenarios'!L3 -> 23.892117 | L3: =13.3+0.118*('Diet Scenarios'!H3*100)-0.13*H3+2.2*F3-1.71*G3+0.00521*D3 -> 17.475738 | M3: =L3/Ingredients!$B$10 -> 0.31402943 | N3: =M3*Ingredients!$B$11 -> 8.7614212 | O3: =E3*(0.337+0.116*F3+0.06*G3) -> 36.6244 | P3: =N3/O3 -> 0.23922361 | Q3: =K3*('Diet Scenarios'!D3*INDEX(Ingredients!$H$2:$H$6,MATCH('Diet Scenarios'!B3,Ingredients!$A$2:$A$6,0))+'Diet Scenarios'!E3*('Diet Scenarios'!F3*Ingredients!$H$5+'Diet Scenarios'!G3*Ingredients!$H$6))+Ingredients!$B$12 -> 9.0042965 | R3: =Q3/(E3/45.359237) -> 10.748106 | S3: =(E3/45.359237)*Ingredients!$B$8 -> 17.592889 | T3: =S3-Q3 -> 8.588592 | U3: =T3/(E3/45.359237) -> 10.251894 | W3: Milk yield (kg/d) | X3: 38
A4: ='Diet Scenarios'!A4 -> S3 | B4: ='Diet Scenarios'!B4 -> Alfalfa haylage | C4: ='Diet Scenarios'!C4 -> 55:45 | D4: =$X$2 -> 650 | E4: =$X$3 -> 38 | F4: =$X$4 -> 3.8 | G4: =$X$5 -> 3.1 | H4: =0.327*E4+12.95*(E4*F4/100)+7.2*(E4*G4/100) -> 39.6074 | I4: =$X$6*D4^0.75 -> 10.298524 | J4: =E4*$X$7 -> 28.12 | K4: =(I4+J4)/'Diet Scenarios'!L4 -> 24.358689 | L4: =13.3+0.118*('Diet Scenarios'!H4*100)-0.13*H4+2.2*F4-1.71*G4+0.00521*D4 -> 17.659818 | M4: =L4/Ingredients!$B$10 -> 0.31733725 | N4: =M4*Ingredients!$B$11 -> 8.8537093 | O4: =E4*(0.337+0.116*F4+0.06*G4) -> 36.6244 | P4: =N4/O4 -> 0.24174346 | Q4: =K4*('Diet Scenarios'!D4*INDEX(Ingredients!$H$2:$H$6,MATCH('Diet Scenarios'!B4,Ingredients!$A$2:$A$6,0))+'Diet Scenarios'!E4*('Diet Scenarios'!F4*Ingredients!$H$5+'Diet Scenarios'!G4*Ingredients!$H$6))+Ingredients!$B$12 -> 9.4709918 | R4: =Q4/(E4/45.359237) -> 11.305183 | S4: =(E4/45.359237)*Ingredients!$B$8 -> 17.592889 | T4: =S4-Q4 -> 8.1218968 | U4: =T4/(E4/45.359237) -> 9.6948168 | W4: Milk fat % | X4: 3.8
A5: ='Diet Scenarios'!A5 -> S4 | B5: ='Diet Scenarios'!B5 -> Corn silage | C5: ='Diet Scenarios'!C5 -> 45:55 | D5: =$X$2 -> 650 | E5: =$X$3 -> 38 | F5: =$X$4 -> 3.8 | G5: =$X$5 -> 3.1 | H5: =0.327*E5+12.95*(E5*F5/100)+7.2*(E5*G5/100) -> 39.6074 | I5: =$X$6*D5^0.75 -> 10.298524 | J5: =E5*$X$7 -> 28.12 | K5: =(I5+J5)/'Diet Scenarios'!L5 -> 21.937146 | L5: =13.3+0.118*('Diet Scenarios'!H5*100)-0.13*H5+2.2*F5-1.71*G5+0.00521*D5 -> 17.557158 | M5: =L5/Ingredients!$B$10 -> 0.31549251 | N5: =M5*Ingredients!$B$11 -> 8.8022409 | O5: =E5*(0.337+0.116*F5+0.06*G5) -> 36.6244 | P5: =N5/O5 -> 0.24033816 | Q5: =K5*('Diet Scenarios'!D5*INDEX(Ingredients!$H$2:$H$6,MATCH('Diet Scenarios'!B5,Ingredients!$A$2:$A$6,0))+'Diet Scenarios'!E5*('Diet Scenarios'!F5*Ingredients!$H$5+'Diet Scenarios'!G5*Ingredients!$H$6))+Ingredients!$B$12 -> 4.9422153 | R5: =Q5/(E5/45.359237) -> 5.8993451 | S5: =(E5/45.359237)*Ingredients!$B$8 -> 17.592889 | T5: =S5-Q5 -> 12.650673 | U5: =T5/(E5/45.359237) -> 15.100655 | W5: Milk true protein % | X5: 3.1
A6: ='Diet Scenarios'!A6 -> S5 | B6: ='Diet Scenarios'!B6 -> Corn silage | C6: ='Diet Scenarios'!C6 -> 50:50 | D6: =$X$2 -> 650 | E6: =$X$3 -> 38 | F6: =$X$4 -> 3.8 | G6: =$X$5 -> 3.1 | H6: =0.327*E6+12.95*(E6*F6/100)+7.2*(E6*G6/100) -> 39.6074 | I6: =$X$6*D6^0.75 -> 10.298524 | J6: =E6*$X$7 -> 28.12 | K6: =(I6+J6)/'Diet Scenarios'!L6 -> 22.168797 | L6: =13.3+0.118*('Diet Scenarios'!H6*100)-0.13*H6+2.2*F6-1.71*G6+0.00521*D6 -> 17.770738 | M6: =L6/Ingredients!$B$10 -> 0.31933042 | N6: =M6*Ingredients!$B$11 -> 8.9093188 | O6: =E6*(0.337+0.116*F6+0.06*G6) -> 36.6244 | P6: =N6/O6 -> 0.24326184 | Q6: =K6*('Diet Scenarios'!D6*INDEX(Ingredients!$H$2:$H$6,MATCH('Diet Scenarios'!B6,Ingredients!$A$2:$A$6,0))+'Diet Scenarios'!E6*('Diet Scenarios'!F6*Ingredients!$H$5+'Diet Scenarios'!G6*Ingredients!$H$6))+Ingredients!$B$12 -> 4.9151441 | R6: =Q6/(E6/45.359237) -> 5.8670312 | S6: =(E6/45.359237)*Ingredients!$B$8 -> 17.592889 | T6: =S6-Q6 -> 12.677744 | U6: =T6/(E6/45.359237) -> 15.132969 | W6: NEmaint coefficient (Mcal/kg^0.75) | X6: 0.08
A7: ='Diet Scenarios'!A7 -> S6 | B7: ='Diet Scenarios'!B7 -> Corn silage | C7: ='Diet Scenarios'!C7 -> 55:45 | D7: =$X$2 -> 650 | E7: =$X$3 -> 38 | F7: =$X$4 -> 3.8 | G7: =$X$5 -> 3.1 | H7: =0.327*E7+12.95*(E7*F7/100)+7.2*(E7*G7/100) -> 39.6074 | I7: =$X$6*D7^0.75 -> 10.298524 | J7: =E7*$X$7 -> 28.12 | K7: =(I7+J7)/'Diet Scenarios'!L7 -> 22.405391 | L7: =13.3+0.118*('Diet Scenarios'!H7*100)-0.13*H7+2.2*F7-1.71*G7+0.00521*D7 -> 17.984318 | M7: =L7/Ingredients!$B$10 -> 0.32316834 | N7: =M7*Ingredients!$B$11 -> 9.0163966 | O7: =E7*(0.337+0.116*F7+0.06*G7) -> 36.6244 | P7: =N7/O7 -> 0.24618551 | Q7: =K7*('Diet Scenarios'!D7*INDEX(Ingredients!$H$2:$H$6,MATCH('Diet Scenarios'!B7,Ingredients!$A$2:$A$6,0))+'Diet Scenarios'!E7*('Diet Scenarios'!F7*Ingredients!$H$5+'Diet Scenarios'!G7*Ingredients!$H$6))+Ingredients!$B$12 -> 4.8874951 | R7: =Q7/(E7/45.359237) -> 5.8340276 | S7: =(E7/45.359237)*Ingredients!$B$8 -> 17.592889 | T7: =S7-Q7 -> 12.705393 | U7: =T7/(E7/45.359237) -> 15.165972 | W7: NEl per kg milk (Mcal/kg, ~3.5% fat basis) | X7: 0.74
A8: ='Diet Scenarios'!A8 -> S7 | B8: ='Diet Scenarios'!B8 -> Grass hay | C8: ='Diet Scenarios'!C8 -> 45:55 | D8: =$X$2 -> 650 | E8: =$X$3 -> 38 | F8: =$X$4 -> 3.8 | G8: =$X$5 -> 3.1 | H8: =0.327*E8+12.95*(E8*F8/100)+7.2*(E8*G8/100) -> 39.6074 | I8: =$X$6*D8^0.75 -> 10.298524 | J8: =E8*$X$7 -> 28.12 | K8: =(I8+J8)/'Diet Scenarios'!L8 -> 24.104985 | L8: =13.3+0.118*('Diet Scenarios'!H8*100)-0.13*H8+2.2*F8-1.71*G8+0.00521*D8 -> 18.247458 | M8: =L8/Ingredients!$B$10 -> 0.32789682 | N8: =M8*Ingredients!$B$11 -> 9.1483213 | O8: =E8*(0.337+0.116*F8+0.06*G8) -> 36.6244 | P8: =N8/O8 -> 0.24978761 | Q8: =K8*('Diet Scenarios'!D8*INDEX(Ingredients!$H$2:$H$6,MATCH('Diet Scenarios'!B8,Ingredients!$A$2:$A$6,0))+'Diet Scenarios'!E8*('Diet Scenarios'!F8*Ingredients!$H$5+'Diet Scenarios'!G8*Ingredients!$H$6))+Ingredients!$B$12 -> 5.5699754 | R8: =Q8/(E8/45.359237) -> 6.6486799 | S8: =(E8/45.359237)*Ingredients!$B$8 -> 17.592889 | T8: =S8-Q8 -> 12.022913 | U8: =T8/(E8/45.359237) -> 14.35132
A9: ='Diet Scenarios'!A9 -> S8 | B9: ='Diet Scenarios'!B9 -> Grass hay | C9: ='Diet Scenarios'!C9 -> 50:50 | D9: =$X$2 -> 650 | E9: =$X$3 -> 38 | F9: =$X$4 -> 3.8 | G9: =$X$5 -> 3.1 | H9: =0.327*E9+12.95*(E9*F9/100)+7.2*(E9*G9/100) -> 39.6074 | I9: =$X$6*D9^0.75 -> 10.298524 | J9: =E9*$X$7 -> 28.12 | K9: =(I9+J9)/'Diet Scenarios'!L9 -> 24.658873 | L9: =13.3+0.118*('Diet Scenarios'!H9*100)-0.13*H9+2.2*F9-1.71*G9+0.00521*D9 -> 18.537738 | M9: =L9/Ingredients!$B$10 -> 0.33311299 | N9: =M9*Ingredients!$B$11 -> 9.2938525 | O9: =E9*(0.337+0.116*F9+0.06*G9) -> 36.6244 | P9: =N9/O9 -> 0.25376122 | Q9: =K9*('Diet Scenarios'!D9*INDEX(Ingredients!$H$2:$H$6,MATCH('Diet Scenarios'!B9,Ingredients!$A$2:$A$6,0))+'Diet Scenarios'!E9*('Diet Scenarios'!F9*Ingredients!$H$5+'Diet Scenarios'!G9*Ingredients!$H$6))+Ingredients!$B$12 -> 5.6256421 | R9: =Q9/(E9/45.359237) -> 6.7151272 | S9: =(E9/45.359237)*Ingredients!$B$8 -> 17.592889 | T9: =S9-Q9 -> 11.967246 | U9: =T9/(E9/45.359237) -> 14.284873
A10: ='Diet Scenarios'!A10 -> S9 | B10: ='Diet Scenarios'!B10 -> Grass hay | C10: ='Diet Scenarios'!C10 -> 55:45 | D10: =$X$2 -> 650 | E10: =$X$3 -> 38 | F10: =$X$4 -> 3.8 | G10: =$X$5 -> 3.1 | H10: =0.327*E10+12.95*(E10*F10/100)+7.2*(E10*G10/100) -> 39.6074 | I10: =$X$6*D10^0.75 -> 10.298524 | J10: =E10*$X$7 -> 28.12 | K10: =(I10+J10)/'Diet Scenarios'!L10 -> 25.238815 | L10: =13.3+0.118*('Diet Scenarios'!H10*100)-0.13*H10+2.2*F10-1.71*G10+0.00521*D10 -> 18.828018 | M10: =L10/Ingredients!$B$10 -> 0.33832916 | N10: =M10*Ingredients!$B$11 -> 9.4393837 | O10: =E10*(0.337+0.116*F10+0.06*G10) -> 36.6244 | P10: =N10/O10 -> 0.25773483 | Q10: =K10*('Diet Scenarios'!D10*INDEX(Ingredients!$H$2:$H$6,MATCH('Diet Scenarios'!B10,Ingredients!$A$2:$A$6,0))+'Diet Scenarios'!E10*('Diet Scenarios'!F10*Ingredients!$H$5+'Diet Scenarios'!G10*Ingredients!$H$6))+Ingredients!$B$12 -> 5.6839273 | R10: =Q10/(E10/45.359237) -> 6.7847001 | S10: =(E10/45.359237)*Ingredients!$B$8 -> 17.592889 | T10: =S10-Q10 -> 11.908961 | U10: =T10/(E10/45.359237) -> 14.2153

Sheet Results
A1: Summary — GHG Intensity vs. Farm Economics Trade-off
A3: Scenario | B3: Forage source | C3: Ratio | D3: GHG intensity (kg CO2e/kg FPCM) | E3: IOFC ($/cwt) | F3: Feed cost ($/cwt) | G3: Marginal cost of GHG reduction ($/cwt per kg CO2e/kg FPCM reduced, vs. lowest-GHG scenario)
A4: =Calculations!A2 -> S1 | B4: =Calculations!B2 -> Alfalfa haylage | C4: =Calculations!C2 -> 45:55 | D4: =Calculations!P2 -> 0.23670376 | E4: =Calculations!U2 -> 10.788032 | F4: =Calculations!R2 -> 10.211968 | G4: =IFERROR((INDEX(E4:E12,MATCH(MIN(D4:D12),D4:D12,0))-E4)/(D4-MIN(D4:D12)),"ref. scenario") -> ref. scenario
A5: =Calculations!A3 -> S2 | B5: =Calculations!B3 -> Alfalfa haylage | C5: =Calculations!C3 -> 50:50 | D5: =Calculations!P3 -> 0.23922361 | E5: =Calculations!U3 -> 10.251894 | F5: =Calculations!R3 -> 10.748106 | G5: =IFERROR((INDEX(E4:E12,MATCH(MIN(D4:D12),D4:D12,0))-E5)/(D5-MIN(D4:D12)),"ref. scenario") -> 212.76552
A6: =Calculations!A4 -> S3 | B6: =Calculations!B4 -> Alfalfa haylage | C6: =Calculations!C4 -> 55:45 | D6: =Calculations!P4 -> 0.24174346 | E6: =Calculations!U4 -> 9.6948168 | F6: =Calculations!R4 -> 11.305183 | G6: =IFERROR((INDEX(E4:E12,MATCH(MIN(D4:D12),D4:D12,0))-E6)/(D6-MIN(D4:D12)),"ref. scenario") -> 216.92046
A7: =Calculations!A5 -> S4 | B7: =Calculations!B5 -> Corn silage | C7: =Calculations!C5 -> 45:55 | D7: =Calculations!P5 -> 0.24033816 | E7: =Calculations!U5 -> 15.100655 | F7: =Calculations!R5 -> 5.8993451 | G7: =IFERROR((INDEX(E4:E12,MATCH(MIN(D4:D12),D4:D12,0))-E7)/(D7-MIN(D4:D12)),"ref. scenario") -> -1186.6112
A8: =Calculations!A6 -> S5 | B8: =Calculations!B6 -> Corn silage | C8: =Calculations!C6 -> 50:50 | D8: =Calculations!P6 -> 0.24326184 | E8: =Calculations!U6 -> 15.132969 | F8: =Calculations!R6 -> 5.8670312 | G8: =IFERROR((INDEX(E4:E12,MATCH(MIN(D4:D12),D4:D12,0))-E8)/(D8-MIN(D4:D12)),"ref. scenario") -> -662.53207
A9: =Calculations!A7 -> S6 | B9: =Calculations!B7 -> Corn silage | C9: =Calculations!C7 -> 55:45 | D9: =Calculations!P7 -> 0.24618551 | E9: =Calculations!U7 -> 15.165972 | F9: =Calculations!R7 -> 5.8340276 | G9: =IFERROR((INDEX(E4:E12,MATCH(MIN(D4:D12),D4:D12,0))-E9)/(D9-MIN(D4:D12)),"ref. scenario") -> -461.7227
A10: =Calculations!A8 -> S7 | B10: =Calculations!B8 -> Grass hay | C10: =Calculations!C8 -> 45:55 | D10: =Calculations!P8 -> 0.24978761 | E10: =Calculations!U8 -> 14.35132 | F10: =Calculations!R8 -> 6.6486799 | G10: =IFERROR((INDEX(E4:E12,MATCH(MIN(D4:D12),D4:D12,0))-E10)/(D10-MIN(D4:D12)),"ref. scenario") -> -272.34249
A11: =Calculations!A9 -> S8 | B11: =Calculations!B9 -> Grass hay | C11: =Calculations!C9 -> 50:50 | D11: =Calculations!P9 -> 0.25376122 | E11: =Calculations!U9 -> 14.284873 | F11: =Calculations!R9 -> 6.7151272 | G11: =IFERROR((INDEX(E4:E12,MATCH(MIN(D4:D12),D4:D12,0))-E11)/(D11-MIN(D4:D12)),"ref. scenario") -> -205.00357
A12: =Calculations!A10 -> S9 | B12: =Calculations!B10 -> Grass hay | C12: =Calculations!C10 -> 55:45 | D12: =Calculations!P10 -> 0.25773483 | E12: =Calculations!U10 -> 14.2153 | F12: =Calculations!R10 -> 6.7847001 | G12: =IFERROR((INDEX(E4:E12,MATCH(MIN(D4:D12),D4:D12,0))-E12)/(D12-MIN(D4:D12)),"ref. scenario") -> -162.96207
A15: Reads as $/cwt of IOFC given up per unit of GHG intensity reduced, by choosing the lowest-GHG-intensity scenario instead of this one. Positive = the low-GHG scenario also costs money (a real mitigation cost). Negative = the low-GHG scenario is ALSO more profitable than this one (mitigation is 'free' or a net gain) - check which sign dominates the table; that sign is the paper's headline economic finding.

Sheet Optimization
A1: Constrained Optimization — Cost of Dietary NDF vs. the Nutritionally Optimal Minimum
A2: Extends Liang, Rutherford & Cabrera (2015, J. Dairy Sci. 98) 'optimal dairy farm management subject to greenhouse gas emissions constraints' to the fiber/hemicellulose mechanism. Diet NDF is swept from the rumen-safe biological/economic minimum (28% DM) up to the upper end of the plausible observed maximum (Mid-Atlantic, 37.2% DM), quantifying the IOFC and GHG cost of running at each commercial NDF range (37.2% DM). Uses the Niu et al. (2018) equation; each point is the true cost-minimizing diet at that NDF level (>=2 forage sources required, rumen-health and acidosis-risk bounds enforced -- see Ingredients tab).
A4: Diet NDF floor (%DM) | B4: Realized GHG intensity (kg CO2e/kg FPCM) | C4: IOFC ($/cwt) | D4: Hemicellulose (%DM) | E4: Diet CP (%DM) | F4: DMI (kg/d) | G4: Alfalfa share | H4: Corn silage share | I4: Grass hay share | J4: Corn grain share | K4: SBM share | L4: Feasible?
A5: 28 | B5: 0.24503865 | C5: 14.635904 | D5: 12.135024 | E5: 16 | F5: 22.403463 | G5: 0 | H5: 0.45 | I5: 0.061 | J5: 0.3011 | K5: 0.1879 | L5: Yes
A6: 30 | B6: 0.24826924 | C6: 14.562818 | D6: 12.836539 | E6: 16 | F6: 22.784912 | G6: 0 | H6: 0.45 | I6: 0.1018 | J6: 0.2624 | K6: 0.1858 | L6: Yes
A7: 32 | B7: 0.25149982 | C7: 14.4872 | D7: 13.538055 | E7: 16 | F7: 23.179577 | G7: 0 | H7: 0.45 | I7: 0.1425 | J7: 0.2238 | K7: 0.1837 | L7: Yes
A8: 32.2 | B8: 0.25182287 | C8: 14.479494 | D8: 13.608207 | E8: 16 | F8: 23.219796 | G8: 0 | H8: 0.45 | I8: 0.1466 | J8: 0.2199 | K8: 0.1835 | L8: Yes
A9: 34 | B9: 0.2547304 | C9: 14.408916 | D9: 14.239571 | E9: 16 | F9: 23.588154 | G9: 0 | H9: 0.45 | I9: 0.1833 | J9: 0.1851 | K9: 0.1816 | L9: Yes
A10: 35 | B10: 0.25634569 | C10: 14.356227 | D10: 14.586471 | E10: 16 | F10: 23.832266 | G10: 0 | H10: 0.4362 | I10: 0.2138 | J10: 0.1703 | K10: 0.1797 | L10: Yes
A11: 36 | B11: 0.25796098 | C11: 14.244353 | D11: 14.915882 | E11: 16 | F11: 24.241831 | G11: 0 | H11: 0.3597 | I11: 0.2903 | J11: 0.1762 | K11: 0.1738 | L11: Yes
A12: 37 | B12: 0.25957627 | C12: 14.128567 | D12: 15.245294 | E12: 16 | F12: 24.665718 | G12: 0 | H12: 0.2832 | I12: 0.3668 | J12: 0.1821 | K12: 0.1679 | L12: Yes
A13: 37.2 | B13: 0.25989932 | C13: 14.104922 | D13: 15.311176 | E13: 16 | F13: 24.752281 | G13: 0 | H13: 0.2679 | I13: 0.3821 | J13: 0.1832 | K13: 0.1668 | L13: Yes
A15: Nutritionally optimal minimum (28% NDF): GHG = 0.2450 kg CO2e/kg FPCM, IOFC = $14.64/cwt | At the upper end of the plausible commercial NDF range (37.2% NDF): GHG = 0.2599, IOFC = $14.10/cwt | Cost of running at this upper range vs. optimum: $0.53/cwt IOFC, +6.1% GHG intensity
A17: CAVEAT: at NDF floors up to ~32%, corn silage sits at its diversification cap (45% of diet DM) with grass hay filling the remainder of the forage requirement; alfalfa does not enter any optimal solution on this frontier under current ARMS-calibrated pricing (Ingredients tab) -- validate against field experience. All solutions enforce >=2 forage sources, a forage-sourced (physically effective) NDF floor of 20% diet DM, and ingredient inclusion caps to avoid SARA-risk corner solutions.

Sheet Validation & Sensitivity
A1: Model Validation & Sensitivity Analysis
A2: Closes four gaps identified before Methods drafting: external validation, price sensitivity, alfalfa-exclusion robustness, and the fixed-milk-composition assumption.
A4: 1. External Validation Against Published Benchmarks
A5: Model quantity | B5: Model range | C5: Published benchmark | D5: Source
A6: Dietary NDF floor | B6: 28.0% DM | C6: Min. 25-30% DM for high producers (lower end OK if forage >=75% of NDF) | D6: NASEM (2021) via MSD Veterinary Manual, Nutritional Requirements of Dairy Cattle
A7: Forage-sourced (physically effective) NDF floor | B7: 20.0% DM | C7: Forage NDF >= 19-21% DM | D7: NASEM (2021)-based TMR formulation guidance (Cattle Daily / extension TMR guides)
A8: Diet NDF range across frontier | B8: 28.0-37.2% DM | C8: 34.1 +/- 4.6% DM (mean +/- SD, large multi-study dataset) | D8: NASEM, Nutrient Requirements of Dairy Cattle, 'Dry Matter Intake' chapter (NCBI Bookshelf NBK600610)
A9: Dietary CP | B9: 16.0-16.5% DM (at LP floor) | C9: 17.8 +/- 1.6% DM | D9: Same NASEM Bookshelf dataset -- model sits ~1 SD low; protein-cost-minimizing corner solution, noted as a limitation
A10: DMI | B10: 22.2-24.8 kg/d | C10: 23.0 +/- 2.8 kg/d | D10: Same NASEM Bookshelf dataset
A11: Body weight | B11: 650 kg (fixed input) | C11: 643 +/- 59 kg | D11: Same NASEM Bookshelf dataset
A12: Real-world diet structure check | B12: Optimizer selects only 2 of 5 forage/ SBM/corn ingredients per point | C12: Example commercial TMR: 37% alfalfa hay + 19% corn silage + 14% corn grain + 30% concentrate mix (i.e., real diets commonly blend 2+ forages incl. alfalfa) | D12: USPTO-filed ruminant feed additive trial documentation, lactating Holstein TMR example
A14: VERDICT: model DMI, BW, and NDF range match published benchmarks closely. CP sits modestly below average (cost-minimizing artifact). The forage-diversity check is the one genuine open flag -- see Section 3.
A16: 2. Price Sensitivity (Tornado): Robustness of the Headline Finding
A17: Baseline headline finding: $0.53/cwt IOFC cost and 6.1% higher GHG intensity when running at the the upper end of the plausible commercial NDF range (37.2% NDF) vs. the nutritional optimum (28% NDF).
A19: Input perturbed (+/-20%, milk price +/-10%) | B19: IOFC gap at -X% | C19: IOFC gap at +X% | D19: Alfalfa enters optimum at either extreme?
A20: Corn silage price | B20: $0.67/cwt | C20: $0.40/cwt | D20: No
A21: Alfalfa price | B21: $0.53/cwt | C21: $0.53/cwt | D21: No
A22: Grass hay price | B22: $0.18/cwt | C22: $0.88/cwt | D22: No
A23: Corn grain price | B23: $0.63/cwt | C23: $0.43/cwt | D23: No
A24: Soybean meal price | B24: $0.54/cwt | C24: $0.52/cwt | D24: No
A25: Milk price | B25: $0.53/cwt | C25: $0.53/cwt | D25: No
A27: VERDICT: the DIRECTION of the finding (higher dietary NDF costs money and GHG) is robust to all tested perturbations. The MAGNITUDE is sensitive, particularly to grass hay price ($0.18-$0.88/cwt range) -- report the baseline as a point estimate with this range disclosed, not as a precise figure.
A29: 3. Why Alfalfa Never Enters the Optimum, and What It Costs to Force It In
A30: Alfalfa was tested at -20% price and still did not enter any optimal solution -- this is a structural result of the 4-attribute (NDF/ADF/CP/NEL) ingredient model, not a fragile price artifact: corn silage + soybean meal replicates alfalfa's NDF/CP/NEL profile more cheaply. Forcing a realistic minimum alfalfa inclusion:
A31: Minimum alfalfa share imposed | B31: Resulting IOFC ($/cwt) | C31: Cost vs. unconstrained optimum ($/cwt)
A32: 0% (unconstrained) | B32: $14.64 | C32: $0.00
A33: 10% | B33: $13.91 | C33: $0.73
A34: 15% (typical industry minimum) | B34: $13.50 | C34: $1.14
A35: 20% | B35: $13.08 | C35: $1.56
A37: VERDICT: alfalfa's exclusion should be reported as a genuine, price-robust model finding, with an explicit limitation that alfalfa's non-nutrient contributions (rumen buffering, palatability, particle-size/chewing stimulation, agronomic risk diversification) are not captured by the 4-attribute ingredient model -- the ~$1.14/cwt cost of a 15% minimum inclusion can be reported as the model's estimate of that unmodeled value.
A39: 4. Fixed Milk Yield/Composition Across Diets -- Literature-Backed Limitation
A40: Published research shows dietary NDF is not neutral to milk yield or composition: increasing dietary NDF is
A41: associated with LOWER milk yield and milk protein %, but HIGHER milk fat % (Ranathunga et al.; peak-lactation NDF-titration
A42: studies, PMC10525722). Fiber:starch ratio also positively affects milk fat % via altered ruminal VFA profile
A43: (acetate:propionate) (Ipharraguerre & Clark framework; cited fiber:starch digestibility trials).
A45: This model holds milk yield, fat%, and protein% constant across all diet/NDF scenarios by design, to isolate the
A46: fiber-cost-emission relationship from confounded production responses (stated in README). Given the literature above,
A47: this is a conservative simplification whose net direction on FPCM and IOFC is NOT unambiguous: higher-NDF diets in
A48: reality would somewhat raise milk fat% (raising FPCM, partly offsetting IOFC loss) while lowering milk yield and
A49: protein% (lowering FPCM, partly reinforcing IOFC loss). The two effects partially oppose each other on FPCM and
...

Sheet Ingredient Library Robustness
A1: Robustness Check: Does a Broader Ingredient Library Change the Headline Finding?
A2: Adds DDGS and soybean hulls to the 5-ingredient library (Ingredients tab) and re-solves the optimization with an NDF CEILING (not floor) swept from 30.0% to 41.7% DM -- the unconstrained economic optimum under this 7-ingredient library, since soybean hulls' cheap, high-NDF, highly digestible fiber shifts the cost-minimizing diet to a much higher crude-NDF composition than the primary 5-ingredient analysis. Directly addresses the reviewer critique that a 5-ingredient library does not reflect commercial U.S. byproduct feeding practice.
A4: NDF ceiling, %DM | B4: GHG intensity, kg CO2e/kg FPCM | C4: IOFC, $/cwt | D4: Corn silage, % | E4: Corn grain, % | F4: SBM, % | G4: DDGS, % | H4: Soybean hulls, % | I4: Alfalfa & grass hay, %
A5: 30 | B5: 0.2483 | C5: 15.32 | D5: 35 | E5: 31.7 | F5: 7.6 | G5: 20 | H5: 5.7 | I5: 0
A6: 32 | B6: 0.2515 | C6: 15.33 | D6: 35 | E6: 28.5 | F6: 7.4 | G6: 20 | H6: 9.1 | I6: 0
A7: 34 | B7: 0.2547 | C7: 15.35 | D7: 35 | E7: 25.4 | F7: 7.1 | G7: 20 | H7: 12.5 | I7: 0
A8: 36 | B8: 0.258 | C8: 15.36 | D8: 35 | E8: 22.2 | F8: 6.9 | G8: 20 | H8: 16 | I8: 0
A9: 38 | B9: 0.2612 | C9: 15.37 | D9: 35 | E9: 19 | F9: 6.6 | G9: 20 | H9: 19.4 | I9: 0
A10: 40 | B10: 0.2617 | C10: 15.37 | D10: 35 | E10: 18.5 | F10: 6.5 | G10: 20 | H10: 20 | I10: 0
A11: 41.7 | B11: 0.2617 | C11: 15.37 | D11: 35 | E11: 18.5 | F11: 6.5 | G11: 20 | H11: 20 | I11: 0
A13: Primary 5-ingredient model (Table 2/Results sheet), comparable NDF range 28.0-37.2%: IOFC gap = $0.53/cwt. This 7-ingredient robustness check, NDF range 30.0-41.7%: IOFC gap = $0.05/cwt -- roughly a 10-fold reduction in the economic magnitude of the fiber-emission trade-off, though its biological direction (higher NDF -> higher GHG) is unchanged.
A15: Note: neither alfalfa haylage nor grass hay enters any solution on this 7-ingredient frontier -- reinforcing, rather than reversing, the primary analysis's finding that a transparent attribute-based optimizer does not select alfalfa once cheaper substitutes for its modeled attributes (NDF, ADF, CP, NEL) are available.
